Workbook

Sheet 일정관리 대시보드
B2: 기술-해외영업 안건 일정관리 대시보드
B3: 기준: 2026-05-29 | 원본: 전체 안건 추적표 | 5월 Rev3 반영 | 신규/지연/To-Do 중심 관리
B5: 전체 안건 | E5: 정상 관리율 | H5: 지연 안건 | K5: 액션 등록률
B6: =COUNT('전체 안건 추적표'!$A$4:$A$37) | E6: =1-COUNTIF('전체 안건 추적표'!$J$4:$J$37,"지연")/COUNT('전체 안건 추적표'!$A$4:$A$37) | H6: =COUNTIF('전체 안건 추적표'!$J$4:$J$37,"지연") | K6: =COUNTIF('전체 안건 추적표'!$L$4:$L$37,"<>-")/COUNT('전체 안건 추적표'!$A$4:$A$37)
B7: 총 추적 대상 | E7: 지연 제외 관리 범위 | H7: 즉시 조치 필요 | K7: To-Do 보유율
B10: 📌 상태별 관리 현황 | F10: 🏭 공장별 진행 밸런스 | L10: 🟢 일정관리 신호등
B11: 상태 | C11: 건수 | D11: 비중 / 관리 바 | F11: 공장 | G11: 전체 | H11: 정상관리 | I11: 지연 | J11: 신규 | L11: 지표 | M11: 현황 | N11: 판정
B12: 완료 | C12: =COUNTIF('전체 안건 추적표'!$J$4:$J$37,B12) | D12: =REPT("■",ROUND(C12/$B$6*20,0))&" "&TEXT(C12/$B$6,"0%") | F12: 창원 | G12: =COUNTIF('전체 안건 추적표'!$B$4:$B$37,F12) | H12: =G12-I12 | I12: =COUNTIFS('전체 안건 추적표'!$B$4:$B$37,F12,'전체 안건 추적표'!$J$4:$J$37,"지연") | J12: =COUNTIFS('전체 안건 추적표'!$B$4:$B$37,F12,'전체 안건 추적표'!$J$4:$J$37,"신규") | L12: 정상 관리율 | M12: =$E$6 | N12: =IF(M12>=0.85,"양호",IF(M12>=0.75,"주의","위험"))
B13: 진행중 | C13: =COUNTIF('전체 안건 추적표'!$J$4:$J$37,B13) | D13: =REPT("■",ROUND(C13/$B$6*20,0))&" "&TEXT(C13/$B$6,"0%") | F13: 광주 | G13: =COUNTIF('전체 안건 추적표'!$B$4:$B$37,F13) | H13: =G13-I13 | I13: =COUNTIFS('전체 안건 추적표'!$B$4:$B$37,F13,'전체 안건 추적표'!$J$4:$J$37,"지연") | J13: =COUNTIFS('전체 안건 추적표'!$B$4:$B$37,F13,'전체 안건 추적표'!$J$4:$J$37,"신규") | L13: 액션 등록률 | M13: =$K$6 | N13: =IF(M13>=0.9,"양호",IF(M13>=0.75,"주의","보완"))
B14: 지연 | C14: =COUNTIF('전체 안건 추적표'!$J$4:$J$37,B14) | D14: =REPT("■",ROUND(C14/$B$6*20,0))&" "&TEXT(C14/$B$6,"0%") | L14: 지연 비중 | M14: =$H$6/$B$6 | N14: =IF(M14<=0.15,"관리 가능",IF(M14<=0.25,"주의","위험"))
B15: 신규 | C15: =COUNTIF('전체 안건 추적표'!$J$4:$J$37,B15) | D15: =REPT("■",ROUND(C15/$B$6*20,0))&" "&TEXT(C15/$B$6,"0%") | L15: 5월 신규 투입 | M15: =COUNTIF('전체 안건 추적표'!$J$4:$J$37,"신규") | N15: =IF(M15>=1,"신규 반영","확인")
B18: ⚠ 즉시 확인 필요 안건 | J18: 🗓 6월 집중 마일스톤
B19: No. | C19: 공장 | D19: 안건명 | E19: 관련부서 | F19: 상태 | G19: 누락/미반영 사유 | H19: 6월 이후 To-Do | J19: 안건명 | K19: 관련부서 | L19: 6월 이후 To-Do
B20: {=IFERROR(_xlfn._xlws.FILTER('전체 안건 추적표'!A4:A37,('전체 안건 추적표'!J4:J37="지연")+(LEFT('전체 안건 추적표'!K4:K37,1)="★")),"")} | C20: {=IFERROR(_xlfn._xlws.FILTER('전체 안건 추적표'!B4:B37,('전체 안건 추적표'!J4:J37="지연")+(LEFT('전체 안건 추적표'!K4:K37,1)="★")),"")} | D20: {=IFERROR(_xlfn._xlws.FILTER('전체 안건 추적표'!C4:C37,('전체 안건 추적표'!J4:J37="지연")+(LEFT('전체 안건 추적표'!K4:K37,1)="★")),"")} | E20: {=IFERROR(_xlfn._xlws.FILTER('전체 안건 추적표'!D4:D37,('전체 안건 추적표'!J4:J37="지연")+(LEFT('전체 안건 추적표'!K4:K37,1)="★")),"")} | F20: {=IFERROR(_xlfn._xlws.FILTER('전체 안건 추적표'!J4:J37,('전체 안건 추적표'!J4:J37="지연")+(LEFT('전체 안건 추적표'!K4:K37,1)="★")),"")} | G20: {=IFERROR(_xlfn._xlws.FILTER('전체 안건 추적표'!K4:K37,('전체 안건 추적표'!J4:J37="지연")+(LEFT('전체 안건 추적표'!K4:K37,1)="★")),"")} | H20: {=IFERROR(_xlfn._xlws.FILTER('전체 안건 추적표'!L4:L37,('전체 안건 추적표'!J4:J37="지연")+(LEFT('전체 안건 추적표'!K4:K37,1)="★")),"")} | J20: {=IFERROR(_xlfn.TAKE(_xlfn._xlws.FILTER('전체 안건 추적표'!C4:C37,ISNUMBER(SEARCH("6",'전체 안건 추적표'!L4:L37))),10),"")} | K20: {=IFERROR(_xlfn.TAKE(_xlfn._xlws.FILTER('전체 안건 추적표'!D4:D37,ISNUMBER(SEARCH("6",'전체 안건 추적표'!L4:L37))),10),"")} | L20: {=IFERROR(_xlfn.TAKE(_xlfn._xlws.FILTER('전체 안건 추적표'!L4:L37,ISNUMBER(SEARCH("6",'전체 안건 추적표'!L4:L37))),10),"")}
B21: 10 | C21: 창원 | D21: BOSCH EU RFQ | E21: OE개발 | F21: 지연 | G21: ★ 3월 회신 예정이었으나 5월까지 미회신 | H21: BOSCH 측 회신 재촉 | J21: 일본향 xEV용 EN 제품 개발 | K21: AP | L21: LN1 PV 완료(~6/15) 바이어 라인업 전환 협의(하반기)
B22: 15 | C22: 광주 | D22: 일본시장 충전제어용(BSJP) | E22: AP | F22: 지연 | G22: ★ RFQ 미제출! 4월에 5월 제출 예정이었으나 미이행 | H22: 영업: BSJP 요구 Spec 재확인(~6월) 기술: 벤치마킹(~6/19) | J22: 일본향 ISS 증대 제품(BSJP) | K22: AP | L22: Q85, S95 2차 PV 결과(~6월)
B23: 27 | C23: 광주 | D23: GB LN1-PN 카바 디자인 변경 | E23: AP | F23: 진행중 | G23: ★ 영업 회신(~4/10) 이후 결과가 5월 자료에 미반영 | H23: 영업 회신 결과 확인 필요 - Club Assist 현재 출장 중으로 차주 업데이트 예정 (26.6.15기준) | J23: 일본시장 충전제어용(BSJP) | K23: AP | L23: 영업: BSJP 요구 Spec 재확인(~6월) 기술: 벤치마킹(~6/19)
B24: 28 | C24: 광주 | D24: 전해액 혼합치구 적합성 검토 | E24: 영업기획 | F24: 진행중 | G24: ★ 방치 후 5월에 재개됨 아직 완료 아님 | H24: 코드 변경 진행 및 변경 확인 회신 촉구 | J24: BCI 65 PH 라인업 확대 | K24: 미주 | L24: 2차 검증 결과보고(~6/20)
B25: 29 | C25: 광주 | D25: 저비중 SG6→SG8 변경 검토 | E25: 영업 | F25: 지연 | G25: ★★ 4개월째 미회신 2월 요청→5월까지 미이행 | H25: 저비중 SG6→SG8 변경 검토 시트 참고 (26. 6. 15 업데이트) | J25: BCI 31 PH 트럭용 개발 | K25: 미주 | L25: 기본성능 검증 및 설계 협의(~6/22) 벤치마킹 보고(~7/30)
B26: 30 | C26: 광주 | D26: 소형 단자 보호캡 형상 변경 | E26: 광주기술 | F26: 진행중 | G26: ★ 바이어 ECR 확인 결과 미반영 | H26: 금형 수정(~8월) 양산(10월 예상) | J26: High Spec B24 개발 | K26: 기술(자체) | L26: 성능 검증(~6월)
J27: High Spec D31 개발 | K27: 기술(자체) | L27: 2차 샘플 생산(~6/20) 성능 검증(~8/30) VC 표기치 협의(~6/5)
J28: 중동향 Smart EFB 개발 | K28: 중아 | L28: 사양 발행 및 양산(6월) LN4 추가 개선 협의(6/1)
J29: JIS 중형 필드수명 개선품 | K29: AP | L29: 영업: 바이어 송부 수량 확인(~6/20) 기술: 홍보자료(~6/12) 샘플 생산(~6/30)
B34: ✅ 관리 포인트 요약
B35: ="총 "&$B$6&"건 중 "&($B$6-$H$6)&"건이 지연 제외 정상 관리 범위이며, 액션 등록률은 "&TEXT($K$6,"0.0%")&"입니다."
B36: ="지연 안건은 "&$H$6&"건으로 별도 추적 리스트에 자동 노출되며, 6월 마일스톤은 우측 리스트에서 바로 확인 가능합니다."
B37: ="5월 신규 안건 "&COUNTIF('전체 안건 추적표'!$J$4:$J$37,"신규")&"건이 반영되어 월간 교류회 후속관리 흐름이 유지되고 있습니다."

Sheet 전체 안건 추적표
A1: 기술-해외영업 월간 교류회 안건 추적 관리표 (2026년 2~5월)
A2: 작성일: 2026.05.29 | 기준: 5월 교류회 자료(Rev3) 반영 | ★ = 5월 자료에서 누락/미반영 항목
A3: No. | B3: 공장 | C3: 안건명 | D3: 관련부서 | E3: 2월 현황 | F3: 3월 현황 | G3: 4월 현황 | H3: 5월 현황 | I3: 6~7월 현황 | J3: 상태 | K3: 5월 누락/미반영 여부 | L3: 6월 이후 To-Do | M3: 6,7월 진행현황
A4: 1 | B4: 창원 | C4: High CCA 1단계 | D4: 미주 | E4: L2~L6 1단계 사양 발행 완료 3자기관(JBI) 평가 진행 중 | F4: (별도 언급 없음 - 1단계 완료 추정) | G4: (별도 언급 없음) | H4: (별도 언급 없음) | J4: 완료 | K4: - | L4: - | M4: (7월 교류회 자료 미언급)
A5: 2 | B5: 창원 | C5: High CCA 2단계 | D5: 미주 | E5: L5/L6 2단계 PV 진행 중(~4월, 품질) | F5: L5,L6 PV 수명 조기종료 분석 중 | G5: L5,L6 PV 수명 조기종료 분석 중 | H5: 5월 자료 미언급 | J5: 진행중 | K5: - | L5: PV 조기종료 원인 분석 완료 필요 | M5: (7월 교류회 자료 미언급)
A6: 3 | B6: 창원 | C6: BCI AGM 24F (차량용) | D6: 미주 | E6: 1,2단계 사양 발행 완료 3자기관 평가 진행 중 | F6: 1,2단계 사양 발행 완료 5월 초도 발주 예상→초도 생산 대비 요청 | G6: 제품 사양 발행 완료 | H6: 양산 中 | J6: 진행중 | K6: - | L6: 초도 생산 진행 | M6: (7월 교류회 자료 미언급)
A7: 4 | B7: 창원 | C7: BCI AGM 24M (마린용) | D7: 미주 | E7: 1차 시료 기본성능 만족, 수명 진행 중 2차 시료 제작 중(~3월초) | F7: 全 시료 기본성능 검증 완료 수명 평가 진행 중(~4월末) | G7: 시료 기본성능 검증 완료 수명 평가 진행 중(~4월말) | H7: 개발평가품 87n 만족, PV 평가中 | J7: 진행중 | K7: - | L7: 수명 평가 결과 확인 | M7: (7월 교류회 자료 미언급)
A8: 5 | B8: 창원 | C8: BCI AGM 27F (차량용) | D8: 미주 | E8: 시운전 일정 수립 중, 라인 보완(~3월) | F8: 시운전 일정 수립 중(~4월) | G8: 시운전 일정 수립 중(~4월) 제품사양 관련 별도 회의 예정 | H8: 미주팀 협의 후 개발치 않기로 협의 완료 | J8: 진행중 | K8: - | L8: 시운전 완료 및 사양 회의 | M8: (7월 교류회 자료 미언급)
A9: 6 | B9: 창원 | C9: BCI AGM 27M (마린용) | D9: 미주 | E9: BCI 24M 검증 후 설계 진행(4월~) | F9: BCI AGM 24M 개발 검증 후 설계 진행(4월~) | G9: BCI AGM 24M 개발 검증 후 설계 검토 진행(5월~) | H9: 설계 검토 中 | J9: 진행중 | K9: - | L9: 설계 검토 진행 | M9: (7월 교류회 자료 미언급)
A10: 7 | B10: 창원 | C10: Club Assist向 CCA 개선품 개발 | D10: 미주 | E10: 설계 검토 중, 시료 제작(~3월) | F10: 1차 시료 제작 완료 2차 시료 자재 수급(~4월) | G10: 1차 시료 기본성능 평가 진행 중 2차 시료 제작(5월 초 격리판 수급) | H10: 1차 시료 평가 : L2 목표치 만족, L4 : 재평가 예정 2차 시료 제작 中 | J10: 진행중 | K10: - | L10: 2차 시료 제작 및 평가 | M10: (7월 교류회 자료 미언급)
A11: 8 | B11: 창원 | C11: AGM 색상 개발 | D11: 미주 | E11: 회색 AGM 사양 발행 완료 추가 색상(노랑,진회색) 개발 완료 →바이어 확인 회신 요청 | F11: 노랑/진회색 개발 완료 바이어 확인 회신 대기 중 추가 색상 개발 가능 | G11: 바이어 확인 회신 대기 중 | H11: FMP 색상 변경 요청 시편 제작(5/28) 시편 영업 송부예정 | J11: 지연 | K11: ★ 바이어 회신 여전히 대기 4개월째 정체 | L11: 바이어 회신 즉시 촉구 | M11: (7월 교류회 자료 미언급)
A12: 9 | B12: 창원 | C12: 대형 AGM 개발 (트럭용) | D12: 유럽 | E12: 설계 완료 및 제조 라인 검토 중 Need/Want 스펙 명확화 필요 | F12: 자재 수급 및 코드 생성 중 시료 제작 예정(~5월) | G12: 자재 수급 및 코드 생성(~5월초) 재공품 제작(~4월말) 격리판 수급 후 시료 제작(5월~) | H12: 6월 시료 제작 예정 | J12: 진행중 | K12: - | L12: 시료 제작 결과 확인 | M12: (7월 교류회 자료 미언급)
A13: 10 | B13: 창원 | C13: BOSCH EU RFQ | D13: OE개발 | E13: 3자기관(ABRL) 시료 송부 완료 평가 결과 회신 예정(26.3월) | F13: 평가 완료 후 결과 회신 예정(26.3월) → 아직 미회신 | G13: BOSCH 평가 결과 회신 대기 중 | H13: BOSCH 평가 결과 회신 대기 중 | J13: 지연 | K13: ★ 3월 회신 예정이었으나 5월까지 미회신 | L13: BOSCH 측 회신 재촉 | M13: (7월 교류회 자료 미언급)
A14: 11 | B14: 창원 | C14: 회색 단자 보호캡 색상 추가 | D14: 유럽 | E14: - | F14: 시운전 결과 비전 검사기 검출 불가 | G14: 비전 검사기 업체와 검출 조건 재설정 시운전 예정(~5월 초) 바이어 재문의→회신 대기 | H14: 바이어 의견 회신 대기 중 내부 협력사와 개선 방안 추가 검토 중 | J14: 진행중 | K14: - | L14: 시운전 결과 확인 | M14: (7월 교류회 자료 미언급)
A15: 12 | B15: 창원 | C15: EU 배터리 법규 대응 | D15: 유럽 | E15: - | F15: 라벨 표기(26.08~), QR 표기(27.02) 해외영업 협조 대응 요청 →별도 회의 진행 | G15: (별도 언급 없음) | H15: 5월 자료 미언급(창원 안건) | J15: 진행중 | K15: - | L15: 라벨 표기 준비(26.08 시행) | M15: (7월 교류회 자료 미언급)
A16: 13 | B16: 광주 | C16: 일본향 xEV용 EN 제품 개발 | D16: AP | E16: 6종 中 5종 개발 완료 Primium LN1 1종 추가 검증(3월 종료 예상) | F16: 5종 개발 완료 LN1 추가 검증 진행 중(4월 종료 예상) | G16: 5종 개발 완료 LN1 추가 검증 진행 중(6월 종료 예상) | H16: ★ 5월 자료 확인: DV 6종 中 6종 完, PV 1종 진행 중 바이어 협의 상황 공유 요청(하반기 라인업 전환) LN1 Standard 라우팅 변경 검토(~8월, DoD 50% 50cyc 진행중) | I16: 개발 결과 보고 완료(6/23) 6종 전 제품 Spec. 합격 완료 LN1 라인업 일원화 위한 라우팅 변경 검토(~8월) | J16: 진행중 | K16: 5월 반영됨(상세 업데이트) | L16: LN1 PV 완료(~6/15) 바이어 라인업 전환 협의(하반기) | M16: ■ 6월 · DV 6종 中 6종 개발 完(26.6월) · Standard·Premium 라인업 구성 및 Spec 협의 完 ■ 7월 · PV 1종 진행 中 · LN1 Standard DOD50% 63cyc 추가 검증 진행(~7/31) · 기본성능 전 형명 목표 만족(C20 100.9~106.8%) ■ 향후계획 · PV 결과보고(~7/31) · LN1 라인업 일원화(라우팅 통합) 검증(~8/20) ■ 협의·요청 · 바이어 협의 상황 공유 요청(영업) — 하반기 라인업 전환 | N16: 일본향 판매 라인업 및 향후 검토 바이어 및 예상물량 확인필요(영업 → 기술)
A17: 14 | B17: 광주 | C17: 일본향 ISS 증대 제품(BSJP) | D17: AP | E17: Q85, S95 PV 재검증 진행 중 Q85: 5월, S95: 6월 종료 예상 | F17: Q85, S95 품질 PV 불만족 ISS 수명 평가(~6월) | G17: Q85, S95 PV 불만족 ISS 수명 평가(~6월) | H17: ★ 5월 자료 확인: 1차 DV 만족, PV에서 Q85,S95 미달 2차 PV 39,600 진행 중 Q85, S95 ISS 수명 평가(~6월) | I17: 2차 PV 목표 ISS 수명 만족 C20 용량 불만족하여 재검증 진행 예정 (강화된 품질 기준(95→103% 이상) 반영 요청) | J17: 진행중 | K17: 5월 반영됨 | L17: Q85, S95 2차 PV 결과(~6월) | M17: ■ 6월 · 2차 성능검증 完 — ISS 수명 만족(Q85 45,558 / S95 50,404 cyc) · C20 용량 불만족 확인(Q85 98.6%) · 베트남 GIA PHAT 양산 지속(4月~, 440대, ISS 3만회 이상) ■ 7월 · 재검증 준비 단계 (별도 진행 사항 기재 없음) ■ 향후계획 · Q85 기본성능 재검증(~9월) ■ 협의·요청 · 강화된 품질기준(95→103% 이상) 반영 여부 품질팀 협의
A18: 15 | B18: 광주 | C18: 일본시장 충전제어용(BSJP) | D18: AP | E18: - | F18: 3월 BSIJP 미팅 결과 충전수입성 < 필드 수명 강조 | G18: 충전수입성→ISS 수명 증대 개발 RFQ 제출 예정(~5월 2째주) | H18: ★ 5월 자료 확인: 충전수입성 개선률 대비 입고전압 리스크→RFQ 미제출 개발방향성 2차 협의 完(5/27) 기술: Delkor 벤치마킹(~6/19), HAMMOND 시험(~9/20) 영업: BSJP 미팅→요구 Spec 재확인(~6월) | I18: 경쟁사(4개 社) 벤치마킹 진행 完 M42 샘플 제작 예정(7/15) 벤치마킹 결과 송부(~7/25) 충전수입성 성능 평가(~7/30) | J18: 지연 | K18: ★ RFQ 미제출! 4월에 5월 제출 예정이었으나 미이행 | L18: 영업: BSJP 요구 Spec 재확인(~6월) 기술: 벤치마킹(~6/19) | M18: ■ 6월 · DV 검증 결과 불만족 — 요구 Spec 대비 80% 수준 · 개선안 도출: 음극 신규 카본 첨가제(원가 상승 약 0.6%) ■ 7월 · 경쟁사 벤치마킹 실시 完(7/10) └ ATLAS·PANASONIC·ENERGYWITH·GS YUASA 비교 · M42 개선샘플 4종 생산 完(7/14, 음극 기판변경+첨가제) · 기본성능 평가 進 中 / 충전수입성 평가(~7/28) ■ 향후계획 · 벤치마킹 시험 결과 기안 상신(7/29) · 추가 개선안 검증 및 DV 결과보고(~9월) ■ 협의·요청 · 영업: BSJP 미팅 후 개발 Spec 공유·요구 Spec 재확인(~7/31) · 개선안 원가 +0.6% 수용 가능 여부 영업 판단 | N18: 벤치마킹 결과 송부 필요(기술 → 영업)
A19: 16 | B19: 광주 | C19: BCI 65 PH 라인업 확대 | D19: 미주 | E19: 샘플 생산 완료(2/20) 기본 성능 시험(~3월말) | F19: 기본 성능 검증 결과 공유 | G19: 활물질 하한치 97%→100% 필요 2차 검증 예정(~5월) | H19: ★ 5월 자료 확인: 1차 검증 완료(108매,120매 용량 96~99%) 활물질 3g 증대 후 재검증 추가 안정화 후 C20 재검증(~6/10) 2차 성능 검증 결과보고(~6/20) | I19: 1. 개발완료보고 완료 2. 양산물량 협의 필요(0.70T 양산 가능 물량 확인필요) | J19: 진행중 | K19: 5월 반영됨(상세 업데이트) | L19: 2차 검증 결과보고(~6/20) | M19: ■ 6월 · 108매·120매 (+)활물질 3g 증대 후 재검증 完 · 2차 샘플 검증 및 개발완료(26.06) · 65-108 C20 100.4~100.8% / 65-120 C20 100.6~101.0% ■ 7월 · 양산 가능 시점 도래(7월~) — Exp/Punch 듀얼코드 판매 ■ 향후계획 · 개발완료에 따른 양산 착수 ■ 협의·요청 · 양산 시점 및 물량 협의 필요
A20: 17 | B20: 광주 | C20: BCI 24 PH 라인업 확대 | D20: 미주 | E20: Ph 라인업 확대 양산 및 설계 검증 진행 중 | F20: 개발 요청 Spec 회의 完(03/13) 요청서 회신 및 검토서(~04/10) | G20: 검토서 진행 完(04/15) 샘플 생산 예정(~04/24) | H20: ★ 5월 자료 확인: 기본성능 검증 完, J2801 2unit 중(~7/10) BCI 24 J2801 PV 평가(~7/12) 결과보고(DV:~7/17, PV:~8/1) Interstate 교체 샘플 15대 송부(~8/30) | I20: 기본 ㆍ 수명성능 검증 完 PPCN 자료 요청중(INTERSTATE) 결과보고(~8/10) INTERSTATE 교체 샘플 필요 X | J20: 진행중 | K20: 5월 반영됨(상세 업데이트) | L20: J2801 PV 평가(~7/12) 결과보고(~7/17) PPCN 자료 요청 | M20: ■ 6월 · 기본성능 검증 完, J2801 수명성능 完(Spec. 合) · DV: C20 83.27(104.1%) / RC 151(100.6%) / CCA 760·43sec · J2801 9unit (Spec. 8↑ 合) ■ 7월 · Interstate 제품교체 Data sheet 양식 회신 대기 中(6/24~) └ Interstate 담당자 휴가로 회신 지연 ■ 향후계획 · DV·PV 결과보고(~8/14) ■ 협의·요청 · Interstate 양식 회신 촉구(영업 협조) | N20: PPCN 자료 양식 수령 필요(INTERSTATE 자료 요청 및 회신 대기중-7/1) (영업 → 기술)
A21: 18 | B21: 광주 | C21: BCI 27 PH 라인업 확대 | D21: 미주 | E21: Ph 라인업 확대 CCA 성능 및 원가 영향성 평가 중 | F21: 개발 요청 Spec 회의 完(03/13) 요청서 회신 및 검토서(~04/10) | G21: 검토서 進 完(04/15) 수명성능 검증 진행 중(~6월) | H21: ★ 5월 자료 확인: 기본성능 검증 完 J2801 8unit Spec 만족 중(~6/17) BCI 27 J2801 PV 평가(~7/12) 결과보고(DV:~7/17, PV:~8/1) | I21: 수명성능 검증 完 활물질 증대용 샘플 추가 제작(7/9) 증대 샘플 기본성능 검증(~7/24) PPCN 자료 요청중(INTERSTATE) 결과보고(~8/10) INTERSTATE 교체 샘플 필요 X | J21: 진행중 | K21: 5월 반영됨(상세 업데이트) | L21: J2801 PV 결과(~7/12) Interstate 샘플 송부(~8/30) | M21: ■ 6월 · J2801 수명성능 完(8unit, Spec. 合) · 활물질 +3g 증대용 (+),(-)극판 및 샘플 제작 完 ■ 7월 · 기본성능 진행 中(~7/31) / 2차 샘플 검증(~7/31) · DV: C20 93.05(103.4%) / RC 185(108.8%) / CCA 820·36sec ■ 향후계획 · BCI 27 DV·PV 검증(~7/31) · DV·PV 결과보고(~8/14) | N21: PPCN 자료 양식 수령 필요(INTERSTATE 자료 요청 및 회신 대기중-7/1) (영업 → 기술)
A22: 19 | B22: 광주 | C22: BCI 31 PH 트럭용 개발 | D22: 미주 | E22: Interstate RFQ 기준 설계 완료 후 검토서 송부(~3월) | F22: 선행 검토/H 完(03/16) 양산품/시험용 샘플 생산(~4월) | G22: 양산품 성능 검증 중(~5월) Punch 샘플 생산(~5월) 경쟁사 벤치마킹 중(~7월) | H22: ★ 5월 자료 확인: 벤치마킹 결과: 경쟁사 모두 저가/성능열세 판단 Punch 개발품 샘플 제작(각10대, ~6/3) 기본성능 검증 후 설계/양산 협의(~6/22) 경쟁사 벤치마킹 결과보고(~7/30) | I22: 1. PH16 1차 샘플 기본성능 검증 完 -용량 만족, CCA 불만족, 수명성능 검증 中 2. 2차 샘플 제작(7/11) -기본 성능 검증 中(~7/24) 3. 2027~2028 신규 RFQ 대응 -M31 기본성능 만족, 수명시험 진행 中 ※검토서 송부, 개발 Spec. 협의 지연 ※공정 중 스티커 부착 가능 유무 선 확인 필요 | J22: 진행중 | K22: 5월 반영됨(상세 업데이트) | L22: 기본성능 검증 및 설계 협의(~6/22) 벤치마킹 보고(~7/30) | M22: ■ 6월 · 선행 검토 샘플 생산 목표(~6/10) 미달 · 검토 결과 송부·개발목표 협의(~6/30) 미달 ■ 7월 · 선행 검토 샘플 생산 完(7/11) — 목표 대비 약 1개월 지연 · 기본성능·수명성능 검증 中(J2801·J2185 4주 시점) · 시험3(132매): MCCA 1197 / C20 106.3 / RC 210 · 개발 검토 결과 기안 상신 中(7/20~) ■ 향후계획 · 경쟁사(아트라스·DTR) 벤치마킹 결과보고(~7/30) · 선행 검토 샘플 수명시험 검증(~10/16) ■ 협의·요청 · 신규 Interstate RFQ 목표 Spec 변경에 따른 개발목표 협의(~7/31) · 성능 목표 영업 협의 필요
A23: 20 | B23: 광주 | C23: High Spec B24 개발 | D23: 기술(자체) | E23: 밸류맵 확보 Delco 벤치마킹 진행 중 | F23: (-)극판 샘플 생산 완료(03/26) 제품 샘플 생산(~4월) 벤치마킹 결과보고(~4월) | G23: 벤치마킹 결과보고 완료(04/13) 시험용 샘플 생산(~4월) | H23: ★ 5월 자료 확인: 벤치마킹 결과보고 完(04/13) 제품 샘플 생산 完(05/07) 기본성능 검증 진행 중(~6월) | I23: 1. 기본성능 검증 完 - 목표 성능 만족 - 기본성능 결과보고 예정(~07/21) 2. SAE J2801 수명성능 검증 진행 中(~8월) - 검증종료 후 종합결과보고 예정 | J23: 진행중 | K23: 5월 반영됨 | L23: 성능 검증(~6월) | M23: ■ 6월 · 성능 평가 진행 (벤치마킹 결과보고 完 04/13, 샘플 생산 完 05/07) ■ 7월 · 성능 평가 및 개발완료(07/20) · C20 59.99(103.4%) / RC 99~101Min(107.6~109.8%) / CCA 39~46sec ■ 향후계획 · 양산 바이어 확보 단계 ■ 협의·요청 · 양산 가능 바이어 확인 요청(영업, ~7/30)
A24: 21 | B24: 광주 | C24: High Spec D31 개발 | D24: 기술(자체) | E24: 밸류맵 확보 Varta 벤치마킹 완료, 수명 평가 중 | F24: 샘플 생산 완료(03/20) 벤치마킹 결과보고(~4월) 수명성능 검증(~6월) | G24: 영업 확인 요청: 고스펙 제품 시장 수요/판매 가능성 | H24: ★ 5월 자료 확인: 미주팀 회신: MCCA/CCA 고스펙 시장 수요 낮음→기본성능 위주 개발 요청 개선1,2 샘플 J2801 6주차 시험 중(~6월) →전해액 Limit→용량 저하 예상 2차 비중 최적화 샘플 생산(~6/20) 양산품 VC 표기치 변경 협의(~6/5) | J24: 진행중 | K24: 5월 반영됨(영업 회신 완료) | L24: 2차 샘플 생산(~6/20) 성능 검증(~8/30) VC 표기치 협의(~6/5) | M24: ■ 6월 · 2차 시험 결과 용량 목표(103%) 미달 — 개선품 20Hr 97.3(102.4%) · 개선품 MCCA 902 / RC 193 / EN CCA 850 / J2801 11주 · VC 표기치 만족 설계변경 협의(~6/12) ■ 7월 · 3차시험(하한치 제품 100% 만족) 진행 결정 · 극판 하한치 중량 선별(~7/22) / 3차 개선샘플 생산(~7/24) ■ 향후계획 · 3차 샘플 기본성능 검증(~8/14) ■ 협의·요청 · 미주팀 회신(MCCA/CCA 고스펙 수요 낮음, 기본성능 위주 요청) 반영 여부 └ 목표 103% 유지 / 100% 하향 확정 필요
A25: 22 | B25: 광주 | C25: 중동향 Smart EFB 개발 | D25: 중아 | E25: 선행 3종 검증 完, 2월 양산 중 추가 4종 검토 중 기본성능 후 양산 예정(4월~) | F25: LN2,D31 만족 / LN4,LN5 불만족(95%) 재검증 후 양산 협의 完(3/18) | G25: LN4,LN5 재검증 후 양산 진행 협의 完 기본성능 만족 시 양산(5월~) | H25: ★ 5월 자료 확인: D26,LN3,LBN4: 양산 중(2월~) LN2,LN4,LN5,D31: DV/PV 完 LN4 99.3% 조건부 合→양산 진행 협의 完(5/19) 추가 개선 방안 협의(6/1) DoD 50%(~5월) 사양 발행 및 양산: 6월 | I25: - | J25: 완료 | K25: 5월 반영됨 | L25: 사양 발행 및 양산(6월) LN4 추가 개선 협의(6/1) | M25: ■ 6월 · LN4 추가 개선방안 협의(6/1, 기술/품질) · 사양 발행 완료(6/10) · D26(S95)·LN3·LBN4 양산 지속(2월~) ■ 7월 · 특이사항 없음 (LN2·LN4·LN5·D31 DV/PV 검증 完 상태 유지) ■ 향후계획 · 현 설계 유지 양산 ■ 협의·요청 · LN4 조건부 合(99.3%) 추가 개선방안 결론 필요 · 개발 완료 종수 확정(요약표 6종 / 세부 7종)
A26: 23 | B26: 광주 | C26: JIS 중형 필드수명 개선품 | D26: AP | E26: High MCCA, 고중량 제품 개발 벤치마킹 및 시장분석 진행 | F26: D26 원가개선 설계 요청(영업) 검토서 재송부 예정(~04/15) | G26: 검토서 확정(~4/28) 영업 요청 반영 재설계 중 벤치마킹 중(~7월) | H26: ★ 5월 자료 확인: 설계 및 양산 적용 일정 확정(5/13) 양산 목표: 11월~ 기술 홍보 자료 작성(~6/12, 기술→영업) 바이어 송부용 수량 확인 필요(~6/20, 영업) DV/PV 샘플+바이어 송부용 생산(~6/30) | I26: 기술 홍보 자료 송부 完(~6/12) 바이어 송부용 수량 확인 完 : 5대 필요 예상 샘플 생산 : 극판 생산 完, 샘플 생산 지연(~7/20) | J26: 진행중 | K26: 5월 반영됨(상세 업데이트) | L26: 영업: 바이어 송부 수량 확인(~6/20) 기술: 홍보자료(~6/12) 샘플 생산(~6/30) | M26: ■ 6월 · 기술 홍보자료 송부 完(~6/12) · 바이어 송부용 수량 확인 完(5대 필요 예상) · 극판 생산 完(~6/15) · 샘플 생산 6/30 목표 → 7/27로 순연 ■ 7월 · DV/PV 및 바이어 송부용 샘플 생산(~7/27) └ 4종 中 1종만 생산 지시, 생산라인 변경에 따른 지연 ■ 향후계획 · 기본성능 검증(~8/20) / 수명성능 검증(~10/20) / 양산(11월~) ■ 협의·요청 · 잔여 3종 생산 일정 확정 필요
A27: 24 | B27: 광주 | C27: EN 중형 필드수명 개선품 | D27: AP | E27: High MCCA, 고중량 제품 개발 벤치마킹 및 시장분석 진행 | F27: D26 원가개선 설계 요청(영업) 검토서 재송부 예정(~04/15) | G27: 검토서 확정(~4/28) 영업 요청 반영 재설계 중 벤치마킹 중(~7월) | H27: ★ 5월 자료 확인: 설계 및 양산 적용 일정 확정(5/13) 양산 목표: 11월~ 기술 홍보 자료 작성(~6/12) DV/PV 샘플+바이어 송부용 생산(~6/30) | I27: 기술 홍보 자료 송부 完(~6/12) 바이어 송부용 수량 확인 完 : 5대 필요 예상 샘플 생산 : 극판 생산 完, 샘플 생산 지연(~7/20) | J27: 진행중 | K27: 5월 반영됨 | L27: 홍보자료(~6/12) 샘플 생산(~6/30) 양산(11월~) | M27: ■ 6월 · 기술 홍보자료 송부 完(~6/12) · 바이어 송부용 수량 확인 完(5대 필요 예상) · 극판 생산 完(~6/15) ■ 7월 · DV/PV 및 바이어 송부용 샘플 생산 完 · 기본성능 검증 진행 中 ■ 향후계획 · 기본성능 검증(~8/20) / 수명성능 검증(~10/20) / 양산(11월~)
A28: 25 | B28: 광주 | C28: 마린용 고용량 M27 개발 | D28: AP | E28: Century Yuasa 요청 스펙 기준 달성 샘플 송부 完 | F28: 검토/H 作成 完(03/16) 자체 DV 완료 / PV 진행 중 | G28: DV 완료 / PV 진행 중 Century Yuasa 시험 현황 공유 요청 | H28: ★ 5월 자료 확인: DV 完, PV 진행 중(170cycle 진행 중) PV 검증(~6월) Century Yuasa 시험 결과 공유(~6월) 양산: 9월 예상 ★ Century 外 추가 바이어 공급 가능성 확인 필요 ★ AP팀: 6월 최종 리포트 회신 예정 확인(5/26) | I28: DOD 50% 수명 검증 결과 (Spec. 100cycle) 기술 : 202cycle 품질 : 164, 209cycle Century : 117cycle Century 시험 시퀀스 및 시험 방법 확인 요청 | J28: 진행중 | K28: 5월 반영됨(상세 업데이트) | L28: PV 검증 완료(~6월) Century 리포트(~6월) 양산(9월 예상) | M28: ■ 6월 · 자체 DV·PV 검증 完 └ C20 100.1~101.3% / CCA 7.51~7.72V └ Endurance 수명: 기술 202cyc, 품질 164·209cyc (Spec. 100cyc) · Century Yuasa 검증 결과 리포트 회신 기한(~6/30) ■ 7월 · 별도 진행 사항 기재 없음 ■ 향후계획 · 양산 9월 예상 ■ 협의·요청 · Century Yuasa 검증 결과 리포트 회신 확인(6/30 기한 경과) · 바이어/양산 시점/물량 회신 요청(AP팀) · Century 外 추가 바이어 공급 가능성 확인
A29: 26 | B29: 광주 | C29: 유럽향 절감형 극판 박판화 | D29: 기술 | E29: Varta 벤치마킹 결과 Punch 0.65T 적용 검토 | F29: 검토서 작성/영업 송부 完(03.17) 샘플 생산 예정(~4월) | G29: (별도 언급 없음) | H29: ★ 5월 자료 확인: 샘플 생산 완료(26.05) 검증 진행 중 | I29: 1. 기본성능 검증 完 2. SAE J2801 수명성능 검증 진행 중(~8월) - 검증 종료 후 종합보고 예정 | J29: 진행중 | K29: 5월 반영됨 | L29: 검증 결과 확인 | M29: ■ 6월 · 기판 두께별 기본성능 검증 完 └ 0.70t: MCCA 611A(VARTA 544A), EN CCA 540A 만족, C20 62.1 └ 원가 0.70t = 기존 양산 PN류(0.95t) 대비 96.8% 수준 · 기본성능 결과 유럽팀 공유 完 ■ 7월 · SAE J2801 수명시험 진행 中(~8/30) · EN DOD 50% 50cycle — VARTA 92cycle 대비 미달 └ 수명종료 원인 분석 中 ■ 향후계획 · J2801 수명성능 검증 완료(~8/30) · DOD 50% 원인 분석 후 설계 재검토 ■ 협의·요청 · PH 0.7T 개발 검토용 목표 사양 요청(LN1~LN6) — 유럽팀 회신 필요
A30: 27 | B30: 광주 | C30: GB LN1-PN 카바 디자인 변경 | D30: AP | E30: 바이어별 변경 가능 여부 확인 요청 | F30: ECR 송부 完(3/26) 바이어별 승인 진행 | G30: ECR 송부 完 영업: 바이어별 회신(~4/10) | H30: ★ 5월 자료 확인: ECR 송부 完(3/26) 영업 회신(~4/10) | J30: 진행중 | K30: ★ 영업 회신(~4/10) 이후 결과가 5월 자료에 미반영 | L30: 영업 회신 결과 확인 필요 - Club Assist 현재 출장 중으로 차주 업데이트 예정 (26.6.15기준) | M30: ■ 6~7월 · ECR 송부 完(3/26) 이후 진전 없음 · 7월 교류회 비고: 영업 회신 지연 中 ■ 협의·요청 · 바이어별 변경 가능 여부 회신 및 기한 재설정 · 3월 송부 후 4개월째 미회신 — 에스컬레이션 검토 | N30: - OE : Bosch JP 적용 중 - 유럽 : YBS 수정 요청 사항 반영 여부 확인 필요 - 중아 : Schnapp 컨펌 완료 - 미주 : 법인향 컨펌 완료 - AP : GS YUASA : 바이어 문의완료. 고객사의 변경 프로세스에 맞춰 관련 서류 제출 예정 CLUB ASSIST: 바이어 문의 완료, 6월 말 출장 시 진행방향 추가 확인 예정
A31: 28 | B31: 광주 | C31: 전해액 혼합치구 적합성 검토 | D31: 영업기획 | E31: 혼합치구 삭제 가능 여부 바이어 협의 요청 | F31: 회신 지연 확인 | G31: 4월 미언급(방치) | H31: ★ 5월 자료 확인: 영업기획 1)변경 가능 여부 지속 업데이트 중 2)코드 변경 여부 확인 중 → 3개월 만에 처음 진행 상황 확인 | I31: 영업기획 : 업데이트 요청 기술팀 별도 요청 메일 발송(7/1) | J31: 진행중 | K31: ★ 방치 후 5월에 재개됨 아직 완료 아님 | L31: 코드 변경 진행 및 변경 확인 회신 촉구 | M31: ■ 6~7월 · 영업기획 1) 변경 가능 여부 지속 업데이트 中 · 영업기획 2) 코드 변경 여부 확인 中 · 7월 교류회 비고: 영업팀별 회신/수합 지연 中 ■ 협의·요청 · 팀별 회신 취합 및 혼합치구 삭제 적용 바이어 현황 확정 · 2월 최초 요청 이후 5개월간 '확인 中' 상태 지속 | N31: 5월 생산 실적 기준 하기 바이어 지속 생산중 - 담당자에게 제품 변경 요청 BORNEO TECHNICAL (THAILAND) LTD. - VC 6/15 ACCU SERVICE NV - VC 6/15 INDUMOVIL PARTS S.I. - VC 6/15 INTERCEL GROUP B.V. - 생산 대기중인 제품 출고 이후 변경 예정 호산무역(주) GLOBAL BATTERIER AB
A32: 29 | B32: 광주 | C32: 저비중 SG6→SG8 변경 검토 | D32: 영업 | E32: 시장별 AMS 차량 점유율 조사 (담당: 영업, ~03/27) | F32: 회신 지연 확인 | G32: 영업 회신 필요(~05월) | H32: ★ 5월 자료 확인: "각 팀별/바이어별 저비중→일반 비중 변경 관련 최종 의견 회신 필요" → 4개월째 영업 미회신, 여전히 "회신 필요" 상태 | J32: 지연 | K32: ★★ 4개월째 미회신 2월 요청→5월까지 미이행 | L32: 저비중 SG6→SG8 변경 검토 시트 참고 (26. 6. 15 업데이트) | M32: ■ 6~7월 · 각 팀별/바이어별 저비중 → 일반 비중 변경 최종 의견 회신 필요 · 7월 교류회 비고: 회신/수합 지연 中 ■ 협의·요청 · 영업 각 팀 최종 의견 회신(즉시) · 2월 요청 이후 6개월째 미회신 · 상세 바이어 현황은 '저비중 SG6→SG8 변경 검토' 시트 참고 | N32: 저비중 SG6→SG8 변경 검토 시트 참고 (26. 6. 15 업데이트)
A33: 30 | B33: 광주 | C33: 소형 단자 보호캡 형상 변경 | D33: 광주기술 | E33: - | F33: - | G33: 금형 수정 및 조립 검증(~8월) 양산 적용(재고 소진 후, 10월 예상) 바이어측 ECR 발행 여부 확인 요청 | H33: 검토서 작성중(~6/8) | J33: 진행중 | K33: ★ 바이어 ECR 확인 결과 미반영 | L33: 금형 수정(~8월) 양산(10월 예상) | M33: (7월 교류회 자료 미언급)
A34: 31 | B34: 광주 | C34: VC 요청 표준 프로세스 확정 | D34: 기술/영업 | E34: - | F34: - | G34: - | H34: ★ 5월 신규: Case별 결재선 확정 요청 양식 개선 영업팀 배포 및 적용(6/1) | I34: - | J34: 신규 | K34: 5월 신규 안건 | L34: 영업팀 배포 및 적용(6/1) | M34: (7월 교류회 자료 미언급)
A35: 32 | B35: 광주 | C35: 기술 문서 요청 프로세스 수립 | D35: 기술/영업 | E35: - | F35: - | G35: - | H35: ★ 5월 신규: Spec & 표기치 일치/불일치별 Case 분류 결재선 확정 영업팀 배포 및 적용(6/1) | I35: - | J35: 신규 | K35: 5월 신규 안건 | L35: 영업팀 배포 및 적용(6/1) | M35: (7월 교류회 자료 미언급)
A36: 33 | B36: 광주 | C36: BCI DT류(70,75,78) CCA 성능 개선 | D36: 기술 | E36: - | F36: - | G36: - | H36: ★ 5월 신규: PH 기판 CCA 미흡→극판매수 증대 설계 전 매수 교차 검증 完, CCA 전 제품 목표 만족 75류 96매/78류 108매: 액량 Limit 용량 미달 →전해액 최적화 재검증(~6월) BOM 변경 예정(~6월 초) | I36: 1. BOM 변경 완료('26.06.24) 2. 75류 96매/78류 108매: 액량 Limit 용량 미달 →전해액 최적화 재검증(~7월) | J36: 신규 | K36: 5월 신규 안건 | L36: BOM 변경(~6월 초) 전해액 최적화(~6월) | M36: (7월 교류회 자료 미언급)
A37: 34 | B37: 광주 | C37: JIS 소형 EFB 충전수입성 증대 개발 | D37: OE개발 | E37: - | F37: - | G37: - | H37: ★ 5월 신규: 벤치마킹(M42, Delkor 2EA) 진행 중 기본성능(~6/15), 충전수입성능(~6/19) 개발 방향성 회의 진행(5/28) BSIJP 협의 및 Spec 확정 예정 | J37: 신규 | K37: 5월 신규 안건 | L37: Spec 확정 후 개발 착수 | M37: ■ 6~7월 · 개발 방향성 회의 진행(5/27) · 벤치마킹 후 BSJP 협의 예정 — 5월 대비 진전 내용 없음 ■ 협의·요청 · BSJP 협의 및 요구 Spec 확정 · No.15(일본시장 충전제어용)와 동일 과제로 보임 — 통합 관리 검토
A38: 35 | B38: 광주 | C38: 독일향 제품 EN CCA 표기치 증대 검토 | D38: 유럽/품질 | E38: - | F38: - | G38: - | H38: - | I38: 1. 요청 리스트 수신 및 검토 (7/2) * 제품내역 : LN0 외 총 15종 2. 샘플 생산요청 완료 (7/9) 3. 기본/수명 성능 검증 진행중 (7/14~) | J38: 신규 | K38: 7월 신규 안건 | L38: 품질팀 결과 공유 및 검토 요청 | M38: (7월 교류회 자료 미언급)

Sheet 5월 이후 액션 아이템
A1: 6월 이후 주요 액션 아이템 목록 (5월 교류회 자료 기반 업데이트)
A2: 작성일: 2026.05.29 | 5월 교류회 자료 Rev3 반영
A3: No. | B3: 우선순위 | C3: 공장 | D3: 안건명 | E3: 담당 | F3: 액션 내용 | G3: 기한 | H3: 비고
A4: 1 | B4: 긴급 | C4: 광주 | D4: 저비중 SG6→SG8 | E4: 영업 | F4: 각 팀별/바이어별 저비중→일반 비중 변경 최종 의견 회신 | G4: 즉시 | H4: ★★ 4개월째 미회신(2월 요청) 5월 자료에도 여전히 "회신 필요" 상태
A5: 2 | B5: 긴급 | C5: 광주 | D5: 충전제어용 BSJP RFQ | E5: 영업/기술 | F5: 영업: BSJP 미팅→요구 Spec 재확인 기술: Delkor 벤치마킹→충전수입성 확인 | G5: 영업: ~6월 기술: ~6/19 | H5: ★ 4월에 5월 제출 예정이었으나 RFQ 미제출 입고전압 리스크로 보류 상태
A6: 3 | B6: 긴급 | C6: 광주 | D6: BCI 65 2차 검증 | E6: 기술 | F6: 활물질 증대 후 C20 재검증 2차 성능 검증 결과보고 | G6: 재검증: ~6/10 결과보고: ~6/20 | H6: 1차 검증에서 108매/120매 용량 미달
A7: 4 | B7: 긴급 | C7: 광주 | D7: High Spec D31 VC 표기치 | E7: 기술/영업 | F7: 양산품 VC 표기치 만족을 위한 제품 변경 협의 | G7: ~6/5 | H7: 전해액 Limit 발생→용량 저하 예상
A8: 5 | B8: 긴급 | C8: 광주 | D8: BCI DT류 CCA BOM 변경 | E8: 기술 | F8: 검증 완료된 CCA 성능 영업 공유 후 BOM 변경 75류 96매/78류 108매 전해액 최적화 | G8: ~6월 초 | H8: 5월 신규 안건, 전 제품 검증 完
A9: 6 | B9: 높음 | C9: 광주 | D9: BCI 24,27 J2801 수명 평가 | E9: 기술 | F9: BCI 24: J2801 2unit 진행 중 BCI 27: J2801 8unit 진행 중(Spec 만족) | G9: BCI 27: ~6/17 BCI 24: ~7/10 | H9: PV 평가(~7/12), 결과보고(DV:~7/17)
A10: 7 | B10: 높음 | C10: 광주 | D10: BCI 31 기본성능 검증/설계 협의 | E10: 기술 | F10: Punch 개발품 샘플 기본성능 검증 설계 및 양산 협의 | G10: ~6/22 | H10: 경쟁사 벤치마킹 결과보고(~7/30)
A11: 8 | B11: 높음 | C11: 광주 | D11: 중동향 SMART EFB 양산 | E11: 기술/영업 | F11: LN4 추가 개선 방안 협의(6/1) 사양 발행 및 양산 착수 | G11: ~6월 | H11: LN4 99.3% 조건부 合
A12: 9 | B12: 높음 | C12: 광주 | D12: JIS/EN 필드수명 개선품 | E12: 기술/영업 | F12: 기술 홍보자료 작성(→영업) 영업: 바이어 송부용 배터리 수량 확인 DV/PV 샘플 및 바이어 송부용 생산 | G12: 홍보자료: ~6/12 수량확인: ~6/20 생산: ~6/30 | H12: 양산 목표: 11월~
A13: 10 | B13: 높음 | C13: 광주 | D13: 마린용 M27 PV 검증/양산 | E13: 기술/AP | F13: PV 검증 완료 Century Yuasa 시험 결과 공유 Century 外 추가 바이어 공급 가능성 확인 | G13: PV/리포트: ~6월 양산: 9월 예상 | H13: AP팀 6월 리포트 회신 예정 확인(5/26)
A14: 11 | B14: 높음 | C14: 광주 | D14: xEV용 LN1 Premium PV | E14: 기술/AP | F14: LN1 Premium DoD 50% PV 완료 바이어 라인업 전환 협의 상황 공유 LN1 Standard 라우팅 변경 검토 | G14: PV: ~6/15 라우팅: ~8월 | H14: 하반기 라인업 전환 예정
A15: 12 | B15: 높음 | C15: 창원 | D15: AGM 색상 개발 바이어 회신 | E15: 영업(미주) | F15: 노랑/진회색 바이어 확인 회신 촉구 추가 색상 Target/예상물량 확인 | G15: 즉시 | H15: ★ 2월부터 4개월째 대기 5월 자료 미언급
... A26: 23 | B26: 보통 | C26: 창원 | D26: EU 배터리 법규 대응 | E26: 기술(창원)/영업 | F26: 라벨 표기 준비, 바이어 확인/라벨 확정 | G26: 26.08 시행 | H26: 영업 협조 필요

Sheet 지연 안건 상세
A1: 지연/미회신 안건 상세 현황 (5월 교류회 반영 업데이트)
A2: 작성일: 2026.05.29 | 5월 교류회 자료 반영 후 상태 변경 포함
A3: No. | B3: 공장 | C3: 안건명 | D3: 최초 요청월 | E3: 요청 내용 | F3: 담당 | G3: 2~4월 경위 | H3: 5월 교류회 반영 상태 | I3: 조치 필요사항
A4: 1 | B4: 광주 | C4: 저비중 SG6→SG8 | D4: 2월 | E4: 시장별 AMS 차량 점유율 조사 (담당: 영업, ~03/27) | F4: 영업팀 | G4: 2월: 영업에 조사 요청(~3/27) 3월: 회신 지연 확인 4월: "바이어별 변경 가능 영업 회신 필요(~05월)" | H4: ★★ 여전히 미회신 5월 자료에도 "각 팀별/바이어별 최종 의견 회신 필요"로 기재 → 4개월째 영업에서 조사 결과를 회신하지 않음 | I4: 영업 각 팀 즉시 회신 촉구 경영진 에스컬레이션 검토
A5: 2 | B5: 광주 | C5: 전해액 혼합치구 검토 | D5: 2월 | E5: 혼합치구 삭제 가능 여부 바이어 협의 요청 | F5: 영업기획 (정재준) | G5: 2월: 바이어 협의 요청 3월: 회신 지연 확인 4월: 아예 미언급(방치) | H5: ★ 5월에 재개됨 "변경 가능 여부 지속 업데이트 중" "코드 변경 여부 확인 중" → 3개월 방치 후 처음 진행 상황 확인 | I5: 지연→재개(개선) 코드 변경 확인 완료 촉구
A6: 3 | B6: 창원 | C6: AGM 색상 개발 (바이어 회신) | D6: 2월 | E6: 회색/노랑/진회색 수지 시편 바이어 확인 회신 요청 | F6: 영업(미주) | G6: 2월: 바이어 확인 회신 요청 3월: 바이어 회신 대기 중 4월: 바이어 확인 회신 대기 중 | H6: ★ 5월 자료 미언급(창원 안건) → 4개월째 바이어 회신 대기 기술에서도 영업에서도 후속 조치 보이지 않음 | I6: 영업(미주): 바이어 회신 즉시 재촉 바이어 무응답 시 대안 검토
A7: 4 | B7: 창원 | C7: BOSCH EU RFQ | D7: 2월 | E7: 3자기관(ABRL) 평가 결과 회신 예정(26.3월) | F7: OE개발 | G7: 2월: 시료 송부 완료, 3월 결과 예정 3월: 결과 회신 예정→미회신 4월: BOSCH 평가 결과 회신 대기 중 | H7: ★ 5월 자료 미언급(창원 안건) → 3월 회신 예정이었으나 5월까지 미회신 후속 조치 불분명 | I7: OE개발: BOSCH/ABRL 재촉 회신 시점 확인 필요
A8: 5 | B8: 광주 | C8: 충전제어용 BSJP RFQ | D8: 3월 | E8: 충전수입성 증대 개발품 RFQ 제출 예정(~5월 2째주) | F8: 기술/영업(AP) | G8: 3월: BSIJP 미팅→필드 수명 강조 4월: RFQ 제출 예정(~5월 2째주) | H8: ★ RFQ 미제출 입고전압 리스크로 보류 개발방향성 2차 협의 完(5/27) → 기술: Delkor 벤치마킹(~6/19) → 영업: BSJP 요구 Spec 재확인(~6월) | I8: 4월 약속 불이행 영업 BSJP 미팅(~6월) 기술 벤치마킹(~6/19)
A9: 6 | B9: 광주 | C9: GB LN1-PN ECR 회신 | D9: 2월 | E9: 바이어별 변경 가능 여부 ECR 필요 자료 회신(~4/10) | F9: 영업(AP) | G9: 2월: 바이어별 확인 요청 3월: ECR 송부 完(3/26), 승인 진행 4월: 영업 회신(~4/10) | H9: ★ 5월 자료: ECR 송부 完(3/26), "영업 회신(~4/10)" 기재 → 4/10 이후 결과가 반영되지 않음 회신 완료 여부 불명확 | I9: 영업 회신 결과 확인 후 5월 자료에 반영 요청

Sheet 5월 누락 미반영 요약
A1: 5월 교류회 자료에서 누락/미반영된 항목 요약
A2: 4월 이전 교류회에서 5월 팔로우업 예정이었으나 5월 자료에 반영되지 않은 항목
A3: No. | B3: 공장 | C3: 안건명 | D3: 약속 내용 | E3: 약속 시점 | F3: 5월 반영 여부 | G3: 판단 근거
A4: 1 | B4: 광주 | C4: 저비중 SG6→SG8 (영업 미회신) | D4: 시장별 AMS 차량 점유율 조사 회신 | E4: 2월 요청→3/27 기한→5월까지 미이행 | F4: 미반영(미회신 지속) | G4: 5월 자료에도 "최종 의견 회신 필요"로 기재 4개월째 영업이 조사 결과를 주지 않음
A5: 2 | B5: 창원 | C5: AGM 색상 개발 (바이어 회신 미수신) | D5: 노랑/진회색 시편 바이어 확인 회신 | E5: 2월 요청→4개월째 대기 | F5: 5월 자료 미언급 | G5: 5월 자료(광주 작성)에 창원 안건 미포함 영업에서 바이어 회신을 받지 못한 상태 지속
A6: 3 | B6: 창원 | C6: BOSCH EU RFQ (결과 미회신) | D6: BOSCH/ABRL 평가 결과 회신 | E6: 3월 회신 예정→5월까지 미수신 | F6: 5월 자료 미언급 | G6: 5월 자료에 창원 안건 미포함 3자기관 평가 결과 3개월째 미회신
A7: 4 | B7: 광주 | C7: GB LN1-PN ECR (영업 회신 결과) | D7: 바이어별 변경 가능 여부/ECR 회신 | E7: 4월: 영업 회신(~4/10) | F7: 결과 미반영 | G7: 5월 자료에 "ECR 송부 完, 영업 회신(~4/10)"만 기재 4/10 이후 결과가 업데이트되지 않음
A8: 5 | B8: 광주 | C8: 충전제어용 BSJP RFQ (기술 미제출) | D8: RFQ 제출(~5월 2째주) | E8: 4월 교류회에서 약속 | F8: 미이행(보류) | G8: 입고전압 리스크로 RFQ 미제출 5월에 개발방향성 2차 협의로 전환 → 약속 불이행이나 사유 있음
A9: 6 | B9: 광주 | C9: 소형 단자 보호캡 (ECR 확인 결과) | D9: 바이어측 ECR 발행 여부 확인 | E9: 4월 교류회 요청 | F9: 5월 자료 미언급 | G9: 4월 신규 안건인데 5월 자료에 후속 내용 없음
A10: 7 | B10: 창원 | C10: 회색 단자 보호캡 (시운전 결과) | D10: 비전 검사기 검출 조건 재설정 시운전 | E10: 4월: ~5월 초 시운전 예정 | F10: 5월 자료 미언급 | G10: 5월 자료(광주 작성)에 창원 안건 미포함
A11: 8 | B11: 창원 | C11: High CCA 2단계 (분석 결과) | D11: L5,L6 PV 조기종료 분석 | E11: 3~4월 분석 중 | F11: 5월 자료 미언급 | G11: 3개월째 "분석 중"으로 결과 미공유
A12: 9 | B12: 창원 | C12: BCI AGM 24M (수명 평가 결과) | D12: 수명 평가 진행 중 | E12: 4월: ~4월말 완료 예정 | F12: 5월 자료 미언급 | G12: 4월말 완료 예정이었으나 결과 미공유
A13: 10 | B13: 창원 | C13: BCI AGM 27F (시운전/사양회의) | D13: 시운전 및 사양 관련 별도 회의 | E13: 4월: ~4월 시운전 | F13: 5월 자료 미언급 | G13: 시운전 결과 및 회의 내용 미공유

Sheet 대시보드
B2: 기술-해외영업 월간 교류회 안건 대시보드
B3: ="기준: 5월 교류회 자료(Rev3) 반영 | 총 "&COUNT('전체 안건 추적표'!A4:A37)&"건 안건 추적 | 자동 집계"
B5: 전체 | C5: 완료 | D5: 진행중 | E5: 지연 | F5: 신규 | G5: ★누락/미반영 | L5: 상태 | M5: 건수
B6: =COUNT('전체 안건 추적표'!A4:A37) | C6: =COUNTIF('전체 안건 추적표'!$J$4:$J$37,"완료") | D6: =COUNTIF('전체 안건 추적표'!$J$4:$J$37,"진행중") | E6: =COUNTIF('전체 안건 추적표'!$J$4:$J$37,"지연") | F6: =COUNTIF('전체 안건 추적표'!$J$4:$J$37,"신규") | G6: =COUNTIF('전체 안건 추적표'!$K$4:$K$37,"★*") | L6: 완료 | M6: =C6
L7: 진행중 | M7: =D6
B8: ■ 공장별 현황 | I8: ■ 관련부서별 안건 수 | L8: 지연 | M8: =E6
B9: 공장 | C9: 전체 | D9: 완료 | E9: 진행중 | F9: 지연 | G9: 신규 | I9: 부서 | J9: 안건 수 | L9: 신규 | M9: =F6
B10: 창원 | C10: =COUNTIF('전체 안건 추적표'!$B$4:$B$37,$B10) | D10: =COUNTIFS('전체 안건 추적표'!$B$4:$B$37,$B10,'전체 안건 추적표'!$J$4:$J$37,"완료") | E10: =COUNTIFS('전체 안건 추적표'!$B$4:$B$37,$B10,'전체 안건 추적표'!$J$4:$J$37,"진행중") | F10: =COUNTIFS('전체 안건 추적표'!$B$4:$B$37,$B10,'전체 안건 추적표'!$J$4:$J$37,"지연") | G10: =COUNTIFS('전체 안건 추적표'!$B$4:$B$37,$B10,'전체 안건 추적표'!$J$4:$J$37,"신규") | I10: 미주 | J10: =COUNTIF('전체 안건 추적표'!$D$4:$D$37,"미주")
B11: 광주 | C11: =COUNTIF('전체 안건 추적표'!$B$4:$B$37,$B11) | D11: =COUNTIFS('전체 안건 추적표'!$B$4:$B$37,$B11,'전체 안건 추적표'!$J$4:$J$37,"완료") | E11: =COUNTIFS('전체 안건 추적표'!$B$4:$B$37,$B11,'전체 안건 추적표'!$J$4:$J$37,"진행중") | F11: =COUNTIFS('전체 안건 추적표'!$B$4:$B$37,$B11,'전체 안건 추적표'!$J$4:$J$37,"지연") | G11: =COUNTIFS('전체 안건 추적표'!$B$4:$B$37,$B11,'전체 안건 추적표'!$J$4:$J$37,"신규") | I11: 유럽 | J11: =COUNTIF('전체 안건 추적표'!$D$4:$D$37,"유럽")
I12: AP | J12: =COUNTIF('전체 안건 추적표'!$D$4:$D$37,"AP")
B13: ⚠ 지연 안건 (즉시 조치 필요) | I13: 기술(자체/광주/기타) | J13: =COUNTIF('전체 안건 추적표'!$D$4:$D$37,"기술*")+COUNTIF('전체 안건 추적표'!$D$4:$D$37,"광주기술")
B14: No. | C14: 공장 | D14: 안건명 | E14: 관련부서 | F14: 5월 누락/미반영 사유 | I14: 영업/영업기획 | J14: =COUNTIF('전체 안건 추적표'!$D$4:$D$37,"영업*")
B15: {=IFERROR(_xlfn._xlws.FILTER('전체 안건 추적표'!A4:A37,'전체 안건 추적표'!J4:J37="지연"),"")} | C15: {=IFERROR(_xlfn._xlws.FILTER('전체 안건 추적표'!B4:B37,'전체 안건 추적표'!J4:J37="지연"),"")} | D15: {=IFERROR(_xlfn._xlws.FILTER('전체 안건 추적표'!C4:C37,'전체 안건 추적표'!J4:J37="지연"),"")} | E15: {=IFERROR(_xlfn._xlws.FILTER('전체 안건 추적표'!D4:D37,'전체 안건 추적표'!J4:J37="지연"),"")} | F15: {=IFERROR(_xlfn._xlws.FILTER('전체 안건 추적표'!K4:K37,'전체 안건 추적표'!J4:J37="지연"),"")} | I15: 기타(중아/OE개발) | J15: =COUNTIF('전체 안건 추적표'!$D$4:$D$37,"중아")+COUNTIF('전체 안건 추적표'!$D$4:$D$37,"OE개발")
B16: 10 | C16: 창원 | D16: BOSCH EU RFQ | E16: OE개발 | F16: ★ 3월 회신 예정이었으나 5월까지 미회신
B17: 15 | C17: 광주 | D17: 일본시장 충전제어용(BSJP) | E17: AP | F17: ★ RFQ 미제출! 4월에 5월 제출 예정이었으나 미이행
B18: 29 | C18: 광주 | D18: 저비중 SG6→SG8 변경 검토 | E18: 영업 | F18: ★★ 4개월째 미회신 2월 요청→5월까지 미이행
B21: ★ 5월 누락/미반영 안건 (추적 필요)
B22: No. | C22: 공장 | D22: 안건명 | E22: 상태 | F22: 누락/미반영 사유
B23: {=IFERROR(_xlfn._xlws.FILTER('전체 안건 추적표'!A4:A37,LEFT('전체 안건 추적표'!K4:K37,1)="★"),"")} | C23: {=IFERROR(_xlfn._xlws.FILTER('전체 안건 추적표'!B4:B37,LEFT('전체 안건 추적표'!K4:K37,1)="★"),"")} | D23: {=IFERROR(_xlfn._xlws.FILTER('전체 안건 추적표'!C4:C37,LEFT('전체 안건 추적표'!K4:K37,1)="★"),"")} | E23: {=IFERROR(_xlfn._xlws.FILTER('전체 안건 추적표'!J4:J37,LEFT('전체 안건 추적표'!K4:K37,1)="★"),"")} | F23: {=IFERROR(_xlfn._xlws.FILTER('전체 안건 추적표'!K4:K37,LEFT('전체 안건 추적표'!K4:K37,1)="★"),"")}
B24: 10 | C24: 창원 | D24: BOSCH EU RFQ | E24: 지연 | F24: ★ 3월 회신 예정이었으나 5월까지 미회신
B25: 15 | C25: 광주 | D25: 일본시장 충전제어용(BSJP) | E25: 지연 | F25: ★ RFQ 미제출! 4월에 5월 제출 예정이었으나 미이행
B26: 27 | C26: 광주 | D26: GB LN1-PN 카바 디자인 변경 | E26: 진행중 | F26: ★ 영업 회신(~4/10) 이후 결과가 5월 자료에 미반영
B27: 28 | C27: 광주 | D27: 전해액 혼합치구 적합성 검토 | E27: 진행중 | F27: ★ 방치 후 5월에 재개됨 아직 완료 아님
B28: 29 | C28: 광주 | D28: 저비중 SG6→SG8 변경 검토 | E28: 지연 | F28: ★★ 4개월째 미회신 2월 요청→5월까지 미이행
B29: 30 | C29: 광주 | D29: 소형 단자 보호캡 형상 변경 | E29: 진행중 | F29: ★ 바이어 ECR 확인 결과 미반영

Sheet 저비중 SG6→SG8 변경 검토
A1: ■ 저비중 SG6→SG8 변경 검토
I2: (단위 : 대)
A3: 팀 | B3: 판매처 | C3: 판매지역(국가) | D3: 판매처 No | E3: 담당자 | F3: 매출수량 | H3: 정상비중 변경 가능여부 | I3: 불가시 사유
F4: 2025 | G4: 2026
A5: 미주팀 | B5: CASA PELLAS SOCIEDAD | D5: 1410542 | E5: 박윤철 | F5: 20 | G5: 80 | H5: O
B6: CORPORACION GRUPO Q | D6: 1400481 | E6: 박윤철 | F6: 7403 | G6: 1443 | H6: X | I6: 바이어 측 마케팅/홍보 진행으로 인해 변경이 불가
B7: HENRI M. ARTY S.A. | D7: 1400566 | E7: 박윤철 | F7: 864 | G7: 906 | H7: X | I7: 바이어 측 마케팅/홍보 진행으로 인해 변경이 불가
B8: IMPORTADORA DE BATER | D8: 1400506 | E8: 박윤철 | F8: 122606 | G8: 21480 | H8: O
B9: LAUGHLIN AND DE GANN | D9: 1400671 | E9: 박윤철 | F9: 8651 | G9: 2050 | H9: X | I9: 바이어 측 마케팅/홍보 진행으로 인해 변경이 불가
B10: LEBRUN S.A. | D10: 1400561 | E10: 박윤철 | F10: 1507 | H10: X | I10: 바이어 측 마케팅/홍보 진행으로 인해 변경이 불가
B11: CHEVROLET SALES (THA | D11: 1410163 | E11: 정한을 | F11: 8089 | G11: 1296 | H11: X | I11: OES 납품용
B12: GENERAL MOTORS OVERS | D12: 1401865 | E12: 정한을 | F12: 4938 | H12: X | I12: OES 납품용
B13: GM AFRICA & MIDDLE E | D13: 1409969 | E13: 정한을 | F13: 2535 | H13: X | I13: OES 납품용
A14: 아시아퍼시픽팀 | B14: Robert Bosch GmbH_(K | D14: 1410128 | E14: 김민지 | F14: 132612 | G14: 45874 | H14: X | I14: Tender 제품으로 변경 불가
B15: (주)세아스코 | D15: 1400976 | E15: 김지원 | F15: 1313 | H15: O
B16: (주)시엘청림코리아 | D16: 1401545 | E16: 김지원 | F16: 704 | G16: 343 | H16: △ | I16: 소량 거래선으로, 협의 가능 예상
B17: H.H. BATTERY TRADING | D17: 1410453 | E17: 김지원 | F17: 5456 | G17: 1361 | H17: X | I17: 과거 당사 선 제안 제품
B18: HANS CORP | D18: 1401401 | E18: 김지원 | F18: 3108 | G18: 1066 | H18: X | I18: 과거 당사 선 제안 제품
B19: HCB TECHNOLOGIES LTD | D19: 1401285 | E19: 김지원 | F19: 9637 | G19: 3618 | H19: X | I19: 과거 당사 선 제안 제품
B20: INNERSBROOK CORP. | D20: 1401506 | E20: 김지원 | F20: 32802 | G20: 11506 | H20: X | I20: 과거 당사 선 제안 제품
B21: PT YHI Indonesia | D21: 1410269 | E21: 김지원 | F21: 4563 | G21: 8539 | H21: X | I21: 동남아 지역의 높은 수요 저비중 전환 후 매출 증가
B22: PT. DIRGAPUTRA EKAPR | D22: 1410258 | E22: 김지원 | F22: 22445 | G22: 15066 | H22: X | I22: 과거 당사 선 제안 제품
B23: YHI CORPORATION (SIN | D23: 1401864 | E23: 김지원 | F23: 19772 | G23: 6147 | H23: X | I23: 과거 당사 선 제안 제품
B24: YHI POWER MALAYSIA S | D24: 1410514 | E24: 김지원 | F24: 9198 | G24: 4212 | H24: X | I24: 과거 당사 선 제안 제품
B25: (주)빌탑 | D25: 1401981 | E25: 응웬퀸뉴 | F25: 26582 | G25: 7711 | H25: X | I25: 동남아 지역의 높은 수요
B26: AUTO WORLD(KOLAO DEV | D26: 1402060 | E26: 응웬퀸뉴 | F26: 3121 | G26: 1390 | H26: △ | I26: 고객과 협의 필요
B27: BORNEO TECHNICAL (TH | D27: 1402028 | E27: 응웬퀸뉴 | F27: 19509 | G27: 19612 | H27: X | I27: 동남아 지역의 높은 수요
B28: DOUGLAS AND SONS LTD | D28: 1402201 | E28: 응웬퀸뉴 | F28: 540 | H28: O
B29: GIA PHAT | C29: 베트남 | D29: 1401977 | E29: 응웬퀸뉴 | F29: 60986 | G29: 18953 | H29: X | I29: 동남아 지역의 높은 수요
B30: Global New Power (Da | D30: 1401583 | E30: 응웬퀸뉴 | F30: 110 | H30: O
B31: MALPY MACHINERY(B) S | D31: 1410409 | E31: 응웬퀸뉴 | F31: 842 | H31: O
B32: Petrobat Trading (OP | D32: 1401813 | E32: 응웬퀸뉴 | F32: 3667 | H32: △ | I32: 소량 거래선으로, 협의 가능 예상
B33: Rocket batteries Ind | D33: 1402148 | E33: 응웬퀸뉴 | F33: 4521 | G33: 692 | H33: △ | I33: 소량 거래선으로, 협의 가능 예상
B34: S.M.S COMPANY LIMITE | D34: 1410321 | E34: 응웬퀸뉴 | F34: 312 | H34: O
B35: Sebang Battery Vina | D35: 1410319 | E35: 응웬퀸뉴 | F35: 21032 | G35: 1565 | H35: X | I35: 동남아 지역의 높은 수요
B36: SONG TIN TELECOM JSC | D36: 1401971 | E36: 응웬퀸뉴 | F36: 59739 | G36: 19108 | H36: X | I36: 동남아 지역의 높은 수요
B37: TPL Industrial Sales | D37: 1409904 | E37: 응웬퀸뉴 | F37: 12301 | G37: 6280 | H37: △ | I37: 소량 거래선으로, 협의 가능 예상
B38: 태우상사주식회사 | D38: 1400543 | E38: 응웬퀸뉴 | F38: 2461 | H38: △ | I38: 소량 거래선으로, 협의 가능 예상
B39: CLUB ASSIST PTY LTD. | D39: 1401250 | E39: 이수랑 | F39: 24112 | G39: 10816 | H39: △ | I39: 고객과 협의 필요
B40: BROAD CO., LTD | D40: 1403029 | E40: 정유정 | F40: 16743 | G40: 1849 | H40: X | I40: 26년 런칭 자사브랜드 포함
...
